Workbook

Sheet Задание
A1: ЛАБОРАТОРНАЯ РАБОТА №6. Планирование потребности в производственной мощности
A2: Вариант № 3
A4: Вариант | B4: № 3
A6: Плановый период | B6: май 2018 г.
A7: Режим работы предприятия | B7: 5-ти дневная рабочая неделя, 1 смена, длительность смены 8 ч
A8: Характер производственного процесса | B8: прерывный
B9: 0.3 | C9: по заданию — 30 % от календарного фонда времени; обоснование выбора базы расчёта — лист «Этап2_ФондВремени», п. 3-4
A11: Количество единиц оборудования
A12: Оборудование | B12: Кол-во единиц, шт.
A13: Оборудование 1 | B13: 2
A14: Оборудование 2 | B14: 2
A15: Оборудование 3 | B15: 1
A16: Оборудование 4 | B16: 3
A17: Оборудование 5 | B17: 4
A18: Оборудование 6 | B18: 4
A19: Оборудование 7 | B19: 1

Sheet Тек_карты_В3
A1: Спецификации и технологические карты (вариант 3) — лист «ОсновныеДанные» файла «ЛР4 ППМ В3.xlsx»
A3: 1. Спецификации (норма расхода компонента на 1 кг изделия)
A4: Изделие (потребитель) | B4: Материал (компонент) | C4: Норма расхода | D4: Ед. изм. | E4: Объём производства изделия-потребителя, кг (ссылка на «Расчет_МРП»)
A5: Фарш говяжий | B5: говядина | C5: 0.8 | D5: кг | E5: =SUMIF(Расчет_МРП!$B$6:$B$15,$A5,Расчет_МРП!$J$6:$J$15) -> 0
A6: Фарш говяжий | B6: яйцо | C6: 2 | D6: шт | E6: =SUMIF(Расчет_МРП!$B$6:$B$15,$A6,Расчет_МРП!$J$6:$J$15) -> 0
A7: Фарш говяжий | B7: лук репчатый | C7: 0.02 | D7: кг | E7: =SUMIF(Расчет_МРП!$B$6:$B$15,$A7,Расчет_МРП!$J$6:$J$15) -> 0
A8: Фарш говяжий | B8: перец | C8: 0.001 | D8: кг | E8: =SUMIF(Расчет_МРП!$B$6:$B$15,$A8,Расчет_МРП!$J$6:$J$15) -> 0
A9: Фарш говяжий | B9: соль | C9: 0.001 | D9: кг | E9: =SUMIF(Расчет_МРП!$B$6:$B$15,$A9,Расчет_МРП!$J$6:$J$15) -> 0
A10: Фарш домашний | B10: говядина | C10: 0.6 | D10: кг | E10: =SUMIF(Расчет_МРП!$B$6:$B$15,$A10,Расчет_МРП!$J$6:$J$15) -> 110
A11: Фарш домашний | B11: свинина | C11: 0.2 | D11: кг | E11: =SUMIF(Расчет_МРП!$B$6:$B$15,$A11,Расчет_МРП!$J$6:$J$15) -> 110
A12: Фарш домашний | B12: яйцо | C12: 2 | D12: шт | E12: =SUMIF(Расчет_МРП!$B$6:$B$15,$A12,Расчет_МРП!$J$6:$J$15) -> 110
A13: Фарш домашний | B13: лук репчатый | C13: 0.02 | D13: кг | E13: =SUMIF(Расчет_МРП!$B$6:$B$15,$A13,Расчет_МРП!$J$6:$J$15) -> 110
A14: Фарш домашний | B14: перец | C14: 0.001 | D14: кг | E14: =SUMIF(Расчет_МРП!$B$6:$B$15,$A14,Расчет_МРП!$J$6:$J$15) -> 110
A15: Фарш домашний | B15: соль | C15: 0.001 | D15: кг | E15: =SUMIF(Расчет_МРП!$B$6:$B$15,$A15,Расчет_МРП!$J$6:$J$15) -> 110
A16: Фарш куриный | B16: тушка цыпленка | C16: 0.6 | D16: кг | E16: =SUMIF(Расчет_МРП!$B$6:$B$15,$A16,Расчет_МРП!$J$6:$J$15) -> 626
... A40: Цыпленок фаршированный | B40: пленка пищевая | C40: 0.2 | D40: м кв | E40: =SUMIF(Расчет_МРП!$B$6:$B$15,$A40,Расчет_МРП!$J$6:$J$15) -> 147.5
A42: 2. Технологические карты
A43: Изделие | B43: Операция | C43: Цех | D43: Размер партии, кг | E43: Трудоёмкость, чел-ч на партию | F43: Станкоёмкость по карте, маш-ч на партию | G43: Станкоёмкость принятая, маш-ч на партию | H43: Оборудование | I43: Станкоёмкость, ч/кг
A44: Фарш говяжий | B44: разрезка мяса на куски | C44: №1 | D44: 100 | E44: 5 | F44: 5 | G44: =IF(F44>0,F44,E44) -> 5 | H44: оборудование 1 | I44: =IFERROR(G44/D44,0) -> 0.05
A45: Фарш говяжий | B45: приготовление фарша | C45: №1 | D45: 100 | E45: 2 | F45: 2 | G45: =IF(F45>0,F45,E45) -> 2 | H45: оборудование 2 | I45: =IFERROR(G45/D45,0) -> 0.02
A46: Фарш домашний | B46: разрезка мяса на куски | C46: №1 | D46: 100 | E46: 5 | F46: 5 | G46: =IF(F46>0,F46,E46) -> 5 | H46: оборудование 1 | I46: =IFERROR(G46/D46,0) -> 0.05
A47: Фарш домашний | B47: приготовление фарша | C47: №1 | D47: 100 | E47: 2 | F47: 2 | G47: =IF(F47>0,F47,E47) -> 2 | H47: оборудование 2 | I47: =IFERROR(G47/D47,0) -> 0.02
A48: Фарш куриный | B48: разрезка мяса на куски | C48: №1 | D48: 100 | E48: 4 | F48: 4 | G48: =IF(F48>0,F48,E48) -> 4 | H48: оборудование 1 | I48: =IFERROR(G48/D48,0) -> 0.04
A49: Фарш куриный | B49: приготовление фарша | C49: №1 | D49: 100 | E49: 1.5 | F49: 1.5 | G49: =IF(F49>0,F49,E49) -> 1.5 | H49: оборудование 2 | I49: =IFERROR(G49/D49,0) -> 0.015
A50: Тесто | B50: приготовление теста | C50: №2 | D50: 10 | E50: 2 | F50: 2 | G50: =IF(F50>0,F50,E50) -> 2 | H50: оборудование 3 | I50: =IFERROR(G50/D50,0) -> 0.2
A51: Пельмени из говядины | B51: Лепка пельменей | C51: №3 | D51: 10 | E51: 0.5 | F51: 0.5 | G51: =IF(F51>0,F51,E51) -> 0.5 | H51: оборудование 4 | I51: =IFERROR(G51/D51,0) -> 0.05
A52: Пельмени из говядины | B52: Заморозка пельменей | C52: №3 | D52: 10 | E52: 0 | F52: 3 | G52: =IF(F52>0,F52,E52) -> 3 | H52: оборудование 5 | I52: =IFERROR(G52/D52,0) -> 0.3
A53: Пельмени домашние | B53: Лепка пельменей | C53: №3 | D53: 10 | E53: 0.5 | F53: 0.5 | G53: =IF(F53>0,F53,E53) -> 0.5 | H53: оборудование 4 | I53: =IFERROR(G53/D53,0) -> 0.05
A54: Пельмени домашние | B54: Заморозка пельменей | C54: №3 | D54: 10 | E54: 0 | F54: 3 | G54: =IF(F54>0,F54,E54) -> 3 | H54: оборудование 5 | I54: =IFERROR(G54/D54,0) -> 0.3
A55: Котлета по киевски | B55: Лепка котлеты | C55: №3 | D55: 10 | E55: 1 | F55: 1 | G55: =IF(F55>0,F55,E55) -> 1 | H55: оборудование 4 | I55: =IFERROR(G55/D55,0) -> 0.1
... A60: Цыпленок фаршированный | B60: упаковка тушки цыпленка | C60: №3 | D60: 10 | E60: 2 | F60: 0 | G60: =IF(F60>0,F60,E60) -> 2 | H60: оборудование 7 | I60: =IFERROR(G60/D60,0) -> 0.2
A62: Примечания:
A63: 1) Станкоёмкость, ч/кг = станкоёмкость принятая, маш-ч на партию ÷ размер партии, кг.
A64: 2) Если в технологической карте станкоёмкость (маш-ч) не указана, но задана трудоёмкость (чел-ч), принимается равная ей величина: операции «фаршировка тушки цыпленка» и «упаковка тушки цыпленка» (оборудование 7) — 2 + 2 = 4 чел-ч на партию 10 кг ⇒ 0,4 ч/кг.
A65: 3) Операция «обвалка котлеты» оборудования не имеет (ручная) — в расчёт мощности не включается.
A66: 4) Спецификация «Пельмени из говядины» в производственную программу не включена: заказов клиентов на неё нет и она не является компонентом другой продукции, поэтому «Фарш говяжий» не производится (см. «Расчет_МРП»).
A67: 5) В технологической карте для операции «выпечка блинов» указан цех «№3»; по описанию цехов в задании выпечка блинов относится к цеху 2 (мучных заготовок) — распределение оборудования по цехам принято по тексту задания (лист «Задание»).
A68: 6) Нулем в графе «Станкоёмкость по карте» отмечены операции, для которых в технологической карте станкоёмкость не задана (трудоёмкость 0 — операция без затрат труда рабочих).

Sheet Склад_Остатки_В3
A1: Остатки на начало планового периода и политика запасов — лист «СкладОстатки» файла «ЛР4 ППМ В3.xlsx»
A3: 1. Готовая продукция (уровень 0)
A4: Изделие | B4: Остаток на начало, кг
A5: Котлеты киевские | B5: 25
A6: Цыплята фаршированные | B6: 40
A7: пельмени домашние | B7: 10
A9: 2. Полуфабрикаты (уровень 1)
A10: Изделие | B10: Остаток на начало, кг
A11: фарш говяжий | B11: 45
A12: фарш куриный | B12: 10
A13: фарш домашний | B13: 70
A15: 3. Материалы (уровень 2)
A16: Материал | B16: Остаток на начало | C16: Ед. изм.
A17: говядина | B17: 50 | C17: кг
A18: свинина | B18: 2 | C18: кг
A19: цыплята (тушка цыпленка) | B19: 70 | C19: кг
A20: яйцо | B20: 80 | C20: шт
A21: лук репчатый | B21: 9 | C21: кг
A22: перец черный | B22: 2 | C22: кг
A23: мука | B23: 50 | C23: кг
A24: соль | B24: 10 | C24: кг
A25: разрыхлитель для теста | B25: 100 | C25: гр
A26: лук зеленый | B26: 15 | C26: кг
A27: петрушка свежая | B27: 5 | C27: кг
A29: 4. Политика запасов (норматив запаса на конец периода)
A30: Группа | B30: Норматив, % от потребности периода
A31: Готовая продукция (уровень 0) | B31: 25
A32: Полуфабрикаты (уровень 1) | B32: 20
A33: Материалы (уровень 2) | B33: 15
A35: Примечания:
A36: 1) В листе «СкладОстатки» позиция B13 названа «фарш говяжий» (70 кг) и дублирует позицию B11; по смыслу (спецификации и заказы) это остаток «Фарша домашнего» — он и использован в расчёте.
A37: 2) Наименования материалов в расчёте приведены к названиям спецификаций («тушка цыпленка», «перец», «петрушка»); количества взяты без изменений.
A38: 3) Остаток «разрыхлителя для теста» задан в граммах (100 гр) и пересчитывается в кг делением на 1000 (см. «Расчет_МРП»).

Sheet Заказы_Клиентов_В3
A1: Заказы клиентов (независимый спрос)
A3: Изделие / материал | B3: Заказ клиентов, кг | C3: Уровень
A4: Котлета по киевски | B4: 300 | C4: 0
A5: Цыпленок фаршированный | B5: 150 | C5: 0
A6: Пельмени домашние | B6: 0 | C6: 0
A7: Блины | B7: 0 | C7: 1
A8: Фарш куриный | B8: 250 | C8: 1
A9: Фарш домашний | B9: 150 | C9: 1
A10: Фарш говяжий | B10: 0 | C10: 1
A11: Тесто | B11: 100 | C11: 1
A13: По «Пельмени домашние», «Блины» и «Фарш говяжий» заказов клиентов нет — объём выпуска определяется зависимой потребностью (а по пельменям она равна нулю).

Sheet Расчет_МРП
A1: Проект производственной программы: расчёт потребности в материалах методом MRP (вариант 3)
A4: Уровень | B4: Изделие / материал | C4: Ед. изм. | D4: Остаток на начало | E4: Заказы клиентов | F4: Зависимая потребность | G4: Общая потребность | H4: Норматив запаса, % | I4: Остаток на конец (норматив) | J4: Объём производства | K4: Объём закупки | L4: Остаток на конец (факт.) | M4: Примечание
A5: Уровень 0. Готовая продукция (норматив запаса — «Склад_Остатки_В3»!B31)
A6: 0 | B6: Котлета по киевски | C6: кг | D6: =Склад_Остатки_В3!$B$5 -> 25 | E6: =Заказы_Клиентов_В3!$B$4 -> 300 | F6: =0 -> 0 | G6: =E6+F6 -> 300 | H6: =Склад_Остатки_В3!$B$31/100 -> 0.25 | I6: =H6*G6 -> 75 | J6: =MAX(0,G6+I6-D6) -> 350 | K6: =0 -> 0 | L6: =D6+J6+K6-G6 -> 75 | M6: Независимый спрос (заказ клиентов). Компонент «Фарш куриный» 0,8 кг/кг → уровень 1
A7: 0 | B7: Цыпленок фаршированный | C7: кг | D7: =Склад_Остатки_В3!$B$6 -> 40 | E7: =Заказы_Клиентов_В3!$B$5 -> 150 | F7: =0 -> 0 | G7: =E7+F7 -> 150 | H7: =Склад_Остатки_В3!$B$31/100 -> 0.25 | I7: =H7*G7 -> 37.5 | J7: =MAX(0,G7+I7-D7) -> 147.5 | K7: =0 -> 0 | L7: =D7+J7+K7-G7 -> 37.5 | M7: Независимый спрос. Компоненты: «Тушка цыпленка» 0,8 (уровень 2), «Блины» 0,2 кг/кг (уровень 1)
A8: 0 | B8: Пельмени домашние | C8: кг | D8: =Склад_Остатки_В3!$B$7 -> 10 | E8: =Заказы_Клиентов_В3!$B$6 -> 0 | F8: =0 -> 0 | G8: =E8+F8 -> 0 | H8: =Склад_Остатки_В3!$B$31/100 -> 0.25 | I8: =H8*G8 -> 0 | J8: =MAX(0,G8+I8-D8) -> 0 | K8: =0 -> 0 | L8: =D8+J8+K8-G8 -> 10 | M8: Заказов клиентов нет; зависимая потребность равна 0 (нет выпуска изделия верхнего уровня)
A10: Уровень 1. Полуфабрикаты (норматив запаса — «Склад_Остатки_В3»!B32)
A11: 1 | B11: Блины | C11: кг | D11: =0 -> 0 | E11: =Заказы_Клиентов_В3!$B$7 -> 0 | F11: =$J$7*SUMIFS(Тек_карты_В3!$C$5:$C$40,Тек_карты_В3!$A$5:$A$40,"Цыпленок фаршированный",Тек_карты_В3!$B$5:$B$40,$B11) -> 29.5 | G11: =E11+F11 -> 29.5 | H11: =Склад_Остатки_В3!$B$32/100 -> 0.2 | I11: =H11*G11 -> 5.9 | J11: =MAX(0,G11+I11-D11) -> 35.4 | K11: =0 -> 0 | L11: =D11+J11+K11-G11 -> 5.9 | M11: Зависимая потребность = объём производства цыплёнка × норма расхода «Блинов» (0,2 кг/кг)
A12: 1 | B12: Фарш куриный | C12: кг | D12: =Склад_Остатки_В3!$B$12 -> 10 | E12: =Заказы_Клиентов_В3!$B$8 -> 250 | F12: =$J$6*SUMIFS(Тек_карты_В3!$C$5:$C$40,Тек_карты_В3!$A$5:$A$40,"Котлета по киевски",Тек_карты_В3!$B$5:$B$40,$B12) -> 280 | G12: =E12+F12 -> 530 | H12: =Склад_Остатки_В3!$B$32/100 -> 0.2 | I12: =H12*G12 -> 106 | J12: =MAX(0,G12+I12-D12) -> 626 | K12: =0 -> 0 | L12: =D12+J12+K12-G12 -> 106 | M12: Зависимая потребность = объём производства котлеты × 0,8 кг/кг
A13: 1 | B13: Фарш домашний | C13: кг | D13: =Склад_Остатки_В3!$B$13 -> 70 | E13: =Заказы_Клиентов_В3!$B$9 -> 150 | F13: =$J$8*SUMIFS(Тек_карты_В3!$C$5:$C$40,Тек_карты_В3!$A$5:$A$40,"Пельмени домашние",Тек_карты_В3!$B$5:$B$40,$B13) -> 0 | G13: =E13+F13 -> 150 | H13: =Склад_Остатки_В3!$B$32/100 -> 0.2 | I13: =H13*G13 -> 30 | J13: =MAX(0,G13+I13-D13) -> 110 | K13: =0 -> 0 | L13: =D13+J13+K13-G13 -> 30 | M13: Зависимая потребность = объём производства пельменей домашних × 0,7 кг/кг (равно 0)
A14: 1 | B14: Фарш говяжий | C14: кг | D14: =Склад_Остатки_В3!$B$11 -> 45 | E14: =Заказы_Клиентов_В3!$B$10 -> 0 | F14: =0 -> 0 | G14: =E14+F14 -> 0 | H14: =Склад_Остатки_В3!$B$32/100 -> 0.2 | I14: =H14*G14 -> 0 | J14: =MAX(0,G14+I14-D14) -> 0 | K14: =0 -> 0 | L14: =D14+J14+K14-G14 -> 45 | M14: «Пельмени из говядины» в программу не входят (нет заказов, нет верхнего уровня) → зависимая потребность 0
A15: 1 | B15: Тесто | C15: кг | D15: =0 -> 0 | E15: =Заказы_Клиентов_В3!$B$11 -> 100 | F15: =$J$11*SUMIFS(Тек_карты_В3!$C$5:$C$40,Тек_карты_В3!$A$5:$A$40,"Блины",Тек_карты_В3!$B$5:$B$40,$B15)+$J$8*SUMIFS(Тек_карты_В3!$C$5:$C$40,Тек_карты_В3!$A$5:$A$40,"Пельмени домашние",Тек_карты_В3!$B$5:$B$40,$B15) -> 28.32 | G15: =E15+F15 -> 128.32 | H15: =Склад_Остатки_В3!$B$32/100 -> 0.2 | I15: =H15*G15 -> 25.664 | J15: =MAX(0,G15+I15-D15) -> 153.984 | K15: =0 -> 0 | L15: =D15+J15+K15-G15 -> 25.664 | M15: Зависимая потребность = объём производства блинов × 0,8 + объём пельменей домашних × 0,3
A16: ИТОГО | B16: Производственная программа (уровни 0-1), кг | J16: =SUM(J6:J8)+SUM(J11:J15) -> 1422.884 | M16: Эти объёмы производства используются далее как «проект производственной программы»
A18: Уровень 2. Закупаемые материалы (норматив запаса — «Склад_Остатки_В3»!B33).
A19: Уровень | B19: Материал | C19: Ед. изм. | D19: Остаток на начало | E19: Заказы клиентов | F19: Зависимая потребность | G19: Общая потребность | H19: Норматив запаса, % | I19: Остаток на конец (норматив) | J19: Объём производства | K19: Объём закупки | L19: Остаток на конец (факт.)
A20: 2 | B20: говядина | C20: кг | D20: =Склад_Остатки_В3!$B$17 -> 50 | E20: =0 -> 0 | F20: =SUMPRODUCT((Тек_карты_В3!$B$5:$B$40=$B20)*Тек_карты_В3!$C$5:$C$40*Тек_карты_В3!$E$5:$E$40) -> 66 | G20: =E20+F20 -> 66 | H20: =Склад_Остатки_В3!$B$33/100 -> 0.15 | I20: =H20*G20 -> 9.9 | J20: =0 -> 0 | K20: =MAX(0,G20+I20-D20) -> 25.9 | L20: =D20+J20+K20-G20 -> 9.9
A21: 2 | B21: свинина | C21: кг | D21: =Склад_Остатки_В3!$B$18 -> 2 | E21: =0 -> 0 | F21: =SUMPRODUCT((Тек_карты_В3!$B$5:$B$40=$B21)*Тек_карты_В3!$C$5:$C$40*Тек_карты_В3!$E$5:$E$40) -> 22 | G21: =E21+F21 -> 22 | H21: =Склад_Остатки_В3!$B$33/100 -> 0.15 | I21: =H21*G21 -> 3.3 | J21: =0 -> 0 | K21: =MAX(0,G21+I21-D21) -> 23.3 | L21: =D21+J21+K21-G21 -> 3.3
A22: 2 | B22: тушка цыпленка | C22: кг | D22: =Склад_Остатки_В3!$B$19 -> 70 | E22: =0 -> 0 | F22: =SUMPRODUCT((Тек_карты_В3!$B$5:$B$40=$B22)*Тек_карты_В3!$C$5:$C$40*Тек_карты_В3!$E$5:$E$40) -> 493.6 | G22: =E22+F22 -> 493.6 | H22: =Склад_Остатки_В3!$B$33/100 -> 0.15 | I22: =H22*G22 -> 74.04 | J22: =0 -> 0 | K22: =MAX(0,G22+I22-D22) -> 497.64 | L22: =D22+J22+K22-G22 -> 74.04
A23: 2 | B23: яйцо | C23: шт | D23: =Склад_Остатки_В3!$B$20 -> 80 | E23: =0 -> 0 | F23: =SUMPRODUCT((Тек_карты_В3!$B$5:$B$40=$B23)*Тек_карты_В3!$C$5:$C$40*Тек_карты_В3!$E$5:$E$40) -> 1625.984 | G23: =E23+F23 -> 1625.984 | H23: =Склад_Остатки_В3!$B$33/100 -> 0.15 | I23: =H23*G23 -> 243.8976 | J23: =0 -> 0 | K23: =MAX(0,G23+I23-D23) -> 1789.8816 | L23: =D23+J23+K23-G23 -> 243.8976
A24: 2 | B24: лук репчатый | C24: кг | D24: =Склад_Остатки_В3!$B$21 -> 9 | E24: =0 -> 0 | F24: =SUMPRODUCT((Тек_карты_В3!$B$5:$B$40=$B24)*Тек_карты_В3!$C$5:$C$40*Тек_карты_В3!$E$5:$E$40) -> 14.72 | G24: =E24+F24 -> 14.72 | H24: =Склад_Остатки_В3!$B$33/100 -> 0.15 | I24: =H24*G24 -> 2.208 | J24: =0 -> 0 | K24: =MAX(0,G24+I24-D24) -> 7.928 | L24: =D24+J24+K24-G24 -> 2.208
A25: 2 | B25: перец | C25: кг | D25: =Склад_Остатки_В3!$B$22 -> 2 | E25: =0 -> 0 | F25: =SUMPRODUCT((Тек_карты_В3!$B$5:$B$40=$B25)*Тек_карты_В3!$C$5:$C$40*Тек_карты_В3!$E$5:$E$40) -> 0.736 | G25: =E25+F25 -> 0.736 | H25: =Склад_Остатки_В3!$B$33/100 -> 0.15 | I25: =H25*G25 -> 0.1104 | J25: =0 -> 0 | K25: =MAX(0,G25+I25-D25) -> 0 | L25: =D25+J25+K25-G25 -> 1.264
A26: 2 | B26: соль | C26: кг | D26: =Склад_Остатки_В3!$B$24 -> 10 | E26: =0 -> 0 | F26: =SUMPRODUCT((Тек_карты_В3!$B$5:$B$40=$B26)*Тек_карты_В3!$C$5:$C$40*Тек_карты_В3!$E$5:$E$40) -> 1.043968 | G26: =E26+F26 -> 1.043968 | H26: =Склад_Остатки_В3!$B$33/100 -> 0.15 | I26: =H26*G26 -> 0.1565952 | J26: =0 -> 0 | K26: =MAX(0,G26+I26-D26) -> 0 | L26: =D26+J26+K26-G26 -> 8.956032
A27: 2 | B27: мука | C27: кг | D27: =Склад_Остатки_В3!$B$23 -> 50 | E27: =0 -> 0 | F27: =SUMPRODUCT((Тек_карты_В3!$B$5:$B$40=$B27)*Тек_карты_В3!$C$5:$C$40*Тек_карты_В3!$E$5:$E$40) -> 138.5856 | G27: =E27+F27 -> 138.5856 | H27: =Склад_Остатки_В3!$B$33/100 -> 0.15 | I27: =H27*G27 -> 20.78784 | J27: =0 -> 0 | K27: =MAX(0,G27+I27-D27) -> 109.37344 | L27: =D27+J27+K27-G27 -> 20.78784
A28: 2 | B28: сахар | C28: кг | D28: =0 -> 0 | E28: =0 -> 0 | F28: =SUMPRODUCT((Тек_карты_В3!$B$5:$B$40=$B28)*Тек_карты_В3!$C$5:$C$40*Тек_карты_В3!$E$5:$E$40) -> 3.07968 | G28: =E28+F28 -> 3.07968 | H28: =Склад_Остатки_В3!$B$33/100 -> 0.15 | I28: =H28*G28 -> 0.461952 | J28: =0 -> 0 | K28: =MAX(0,G28+I28-D28) -> 3.541632 | L28: =D28+J28+K28-G28 -> 0.461952
A29: 2 | B29: разрыхлитель для теста | C29: кг | D29: =Склад_Остатки_В3!$B$25/1000 -> 0.1 | E29: =0 -> 0 | F29: =SUMPRODUCT((Тек_карты_В3!$B$5:$B$40=$B29)*Тек_карты_В3!$C$5:$C$40*Тек_карты_В3!$E$5:$E$40) -> 0.461952 | G29: =E29+F29 -> 0.461952 | H29: =Склад_Остатки_В3!$B$33/100 -> 0.15 | I29: =H29*G29 -> 0.0692928 | J29: =0 -> 0 | K29: =MAX(0,G29+I29-D29) -> 0.4312448 | L29: =D29+J29+K29-G29 -> 0.0692928
A30: 2 | B30: масло сливочное | C30: кг | D30: =0 -> 0 | E30: =0 -> 0 | F30: =SUMPRODUCT((Тек_карты_В3!$B$5:$B$40=$B30)*Тек_карты_В3!$C$5:$C$40*Тек_карты_В3!$E$5:$E$40) -> 77.08 | G30: =E30+F30 -> 77.08 | H30: =Склад_Остатки_В3!$B$33/100 -> 0.15 | I30: =H30*G30 -> 11.562 | J30: =0 -> 0 | K30: =MAX(0,G30+I30-D30) -> 88.642 | L30: =D30+J30+K30-G30 -> 11.562
A31: 2 | B31: сухари панировочные | C31: кг | D31: =0 -> 0 | E31: =0 -> 0 | F31: =SUMPRODUCT((Тек_карты_В3!$B$5:$B$40=$B31)*Тек_карты_В3!$C$5:$C$40*Тек_карты_В3!$E$5:$E$40) -> 70 | G31: =E31+F31 -> 70 | H31: =Склад_Остатки_В3!$B$33/100 -> 0.15 | I31: =H31*G31 -> 10.5 | J31: =0 -> 0 | K31: =MAX(0,G31+I31-D31) -> 80.5 | L31: =D31+J31+K31-G31 -> 10.5
A32: 2 | B32: петрушка | C32: кг | D32: =Склад_Остатки_В3!$B$27 -> 5 | E32: =0 -> 0 | F32: =SUMPRODUCT((Тек_карты_В3!$B$5:$B$40=$B32)*Тек_карты_В3!$C$5:$C$40*Тек_карты_В3!$E$5:$E$40) -> 24.875 | G32: =E32+F32 -> 24.875 | H32: =Склад_Остатки_В3!$B$33/100 -> 0.15 | I32: =H32*G32 -> 3.73125 | J32: =0 -> 0 | K32: =MAX(0,G32+I32-D32) -> 23.60625 | L32: =D32+J32+K32-G32 -> 3.73125
A33: 2 | B33: лук зеленый | C33: кг | D33: =Склад_Остатки_В3!$B$26 -> 15 | E33: =0 -> 0 | F33: =SUMPRODUCT((Тек_карты_В3!$B$5:$B$40=$B33)*Тек_карты_В3!$C$5:$C$40*Тек_карты_В3!$E$5:$E$40) -> 29.5 | G33: =E33+F33 -> 29.5 | H33: =Склад_Остатки_В3!$B$33/100 -> 0.15 | I33: =H33*G33 -> 4.425 | J33: =0 -> 0 | K33: =MAX(0,G33+I33-D33) -> 18.925 | L33: =D33+J33+K33-G33 -> 4.425
A34: 2 | B34: пленка пищевая | C34: м кв | D34: =0 -> 0 | E34: =0 -> 0 | F34: =SUMPRODUCT((Тек_карты_В3!$B$5:$B$40=$B34)*Тек_карты_В3!$C$5:$C$40*Тек_карты_В3!$E$5:$E$40) -> 29.5 | G34: =E34+F34 -> 29.5 | H34: =Склад_Остатки_В3!$B$33/100 -> 0.15 | I34: =H34*G34 -> 4.425 | J34: =0 -> 0 | K34: =MAX(0,G34+I34-D34) -> 33.925 | L34: =D34+J34+K34-G34 -> 4.425

Sheet Этап1_УсловнаяЕдиница
A1: Этап 1. Условная единица — норма станкоёмкости условного изделия по видам оборудования
A2: Условная единица — 1 кг усреднённого изделия производственной программы. Норма станкоёмкости условного изделия по j-му виду оборудования = Σ (станкоёмкость изделия i, ч/кг × удельный вес изделия i в программе).
A4: 1. Производственная программа и удельные веса изделий
A5: Изделие | B5: Объём производства, кг (= Расчет_МРП) | C5: Удельный вес в программе | D5: Цех (по заданию)
A6: Котлета по киевски | B6: =Расчет_МРП!J6 -> 350 | C6: =B6/$B$14 -> 0.24597929 | D6: Цех 3 (готовой продукции)
A7: Цыпленок фаршированный | B7: =Расчет_МРП!J7 -> 147.5 | C7: =B7/$B$14 -> 0.1036627 | D7: Цех 3 (готовой продукции)
A8: Пельмени домашние | B8: =Расчет_МРП!J8 -> 0 | C8: =B8/$B$14 -> 0 | D8: Цех 3 (готовой продукции)
A9: Блины | B9: =Расчет_МРП!J11 -> 35.4 | C9: =B9/$B$14 -> 0.024879048 | D9: Цех 2 (мучных заготовок)
A10: Фарш куриный | B10: =Расчет_МРП!J12 -> 626 | C10: =B10/$B$14 -> 0.43995154 | D10: Цех 1 (разделочный)
A11: Фарш домашний | B11: =Расчет_МРП!J13 -> 110 | C11: =B11/$B$14 -> 0.077307778 | D11: Цех 1 (разделочный)
A12: Фарш говяжий | B12: =Расчет_МРП!J14 -> 0 | C12: =B12/$B$14 -> 0 | D12: Цех 1 (разделочный)
A13: Тесто | B13: =Расчет_МРП!J15 -> 153.984 | C13: =B13/$B$14 -> 0.10821964 | D13: Цех 2 (мучных заготовок)
A14: ИТОГО по программе | B14: =SUM(B6:B13) -> 1422.884 | C14: =SUM(C6:C13) -> 1
A16: 2. Нормы станкоёмкости изделий по видам оборудования, ч/кг (из технологических карт)
A17: Изделие | B17: оборудование 1 | C17: оборудование 2 | D17: оборудование 3 | E17: оборудование 4 | F17: оборудование 5 | G17: оборудование 6 | H17: оборудование 7
A18: Котлета по киевски | B18: =SUMIFS(Тек_карты_В3!$I$44:$I$60,Тек_карты_В3!$A$44:$A$60,$A18,Тек_карты_В3!$H$44:$H$60,B$17) -> 0 | C18: =SUMIFS(Тек_карты_В3!$I$44:$I$60,Тек_карты_В3!$A$44:$A$60,$A18,Тек_карты_В3!$H$44:$H$60,C$17) -> 0 | D18: =SUMIFS(Тек_карты_В3!$I$44:$I$60,Тек_карты_В3!$A$44:$A$60,$A18,Тек_карты_В3!$H$44:$H$60,D$17) -> 0 | E18: =SUMIFS(Тек_карты_В3!$I$44:$I$60,Тек_карты_В3!$A$44:$A$60,$A18,Тек_карты_В3!$H$44:$H$60,E$17) -> 0.1 | F18: =SUMIFS(Тек_карты_В3!$I$44:$I$60,Тек_карты_В3!$A$44:$A$60,$A18,Тек_карты_В3!$H$44:$H$60,F$17) -> 0.3 | G18: =SUMIFS(Тек_карты_В3!$I$44:$I$60,Тек_карты_В3!$A$44:$A$60,$A18,Тек_карты_В3!$H$44:$H$60,G$17) -> 0 | H18: =SUMIFS(Тек_карты_В3!$I$44:$I$60,Тек_карты_В3!$A$44:$A$60,$A18,Тек_карты_В3!$H$44:$H$60,H$17) -> 0
A19: Цыпленок фаршированный | B19: =SUMIFS(Тек_карты_В3!$I$44:$I$60,Тек_карты_В3!$A$44:$A$60,$A19,Тек_карты_В3!$H$44:$H$60,B$17) -> 0 | C19: =SUMIFS(Тек_карты_В3!$I$44:$I$60,Тек_карты_В3!$A$44:$A$60,$A19,Тек_карты_В3!$H$44:$H$60,C$17) -> 0 | D19: =SUMIFS(Тек_карты_В3!$I$44:$I$60,Тек_карты_В3!$A$44:$A$60,$A19,Тек_карты_В3!$H$44:$H$60,D$17) -> 0 | E19: =SUMIFS(Тек_карты_В3!$I$44:$I$60,Тек_карты_В3!$A$44:$A$60,$A19,Тек_карты_В3!$H$44:$H$60,E$17) -> 0 | F19: =SUMIFS(Тек_карты_В3!$I$44:$I$60,Тек_карты_В3!$A$44:$A$60,$A19,Тек_карты_В3!$H$44:$H$60,F$17) -> 0 | G19: =SUMIFS(Тек_карты_В3!$I$44:$I$60,Тек_карты_В3!$A$44:$A$60,$A19,Тек_карты_В3!$H$44:$H$60,G$17) -> 0 | H19: =SUMIFS(Тек_карты_В3!$I$44:$I$60,Тек_карты_В3!$A$44:$A$60,$A19,Тек_карты_В3!$H$44:$H$60,H$17) -> 0.4
A20: Пельмени домашние | B20: =SUMIFS(Тек_карты_В3!$I$44:$I$60,Тек_карты_В3!$A$44:$A$60,$A20,Тек_карты_В3!$H$44:$H$60,B$17) -> 0 | C20: =SUMIFS(Тек_карты_В3!$I$44:$I$60,Тек_карты_В3!$A$44:$A$60,$A20,Тек_карты_В3!$H$44:$H$60,C$17) -> 0 | D20: =SUMIFS(Тек_карты_В3!$I$44:$I$60,Тек_карты_В3!$A$44:$A$60,$A20,Тек_карты_В3!$H$44:$H$60,D$17) -> 0 | E20: =SUMIFS(Тек_карты_В3!$I$44:$I$60,Тек_карты_В3!$A$44:$A$60,$A20,Тек_карты_В3!$H$44:$H$60,E$17) -> 0.05 | F20: =SUMIFS(Тек_карты_В3!$I$44:$I$60,Тек_карты_В3!$A$44:$A$60,$A20,Тек_карты_В3!$H$44:$H$60,F$17) -> 0.3 | G20: =SUMIFS(Тек_карты_В3!$I$44:$I$60,Тек_карты_В3!$A$44:$A$60,$A20,Тек_карты_В3!$H$44:$H$60,G$17) -> 0 | H20: =SUMIFS(Тек_карты_В3!$I$44:$I$60,Тек_карты_В3!$A$44:$A$60,$A20,Тек_карты_В3!$H$44:$H$60,H$17) -> 0
A21: Блины | B21: =SUMIFS(Тек_карты_В3!$I$44:$I$60,Тек_карты_В3!$A$44:$A$60,$A21,Тек_карты_В3!$H$44:$H$60,B$17) -> 0 | C21: =SUMIFS(Тек_карты_В3!$I$44:$I$60,Тек_карты_В3!$A$44:$A$60,$A21,Тек_карты_В3!$H$44:$H$60,C$17) -> 0 | D21: =SUMIFS(Тек_карты_В3!$I$44:$I$60,Тек_карты_В3!$A$44:$A$60,$A21,Тек_карты_В3!$H$44:$H$60,D$17) -> 0 | E21: =SUMIFS(Тек_карты_В3!$I$44:$I$60,Тек_карты_В3!$A$44:$A$60,$A21,Тек_карты_В3!$H$44:$H$60,E$17) -> 0 | F21: =SUMIFS(Тек_карты_В3!$I$44:$I$60,Тек_карты_В3!$A$44:$A$60,$A21,Тек_карты_В3!$H$44:$H$60,F$17) -> 0 | G21: =SUMIFS(Тек_карты_В3!$I$44:$I$60,Тек_карты_В3!$A$44:$A$60,$A21,Тек_карты_В3!$H$44:$H$60,G$17) -> 0.1 | H21: =SUMIFS(Тек_карты_В3!$I$44:$I$60,Тек_карты_В3!$A$44:$A$60,$A21,Тек_карты_В3!$H$44:$H$60,H$17) -> 0
A22: Фарш куриный | B22: =SUMIFS(Тек_карты_В3!$I$44:$I$60,Тек_карты_В3!$A$44:$A$60,$A22,Тек_карты_В3!$H$44:$H$60,B$17) -> 0.04 | C22: =SUMIFS(Тек_карты_В3!$I$44:$I$60,Тек_карты_В3!$A$44:$A$60,$A22,Тек_карты_В3!$H$44:$H$60,C$17) -> 0.015 | D22: =SUMIFS(Тек_карты_В3!$I$44:$I$60,Тек_карты_В3!$A$44:$A$60,$A22,Тек_карты_В3!$H$44:$H$60,D$17) -> 0 | E22: =SUMIFS(Тек_карты_В3!$I$44:$I$60,Тек_карты_В3!$A$44:$A$60,$A22,Тек_карты_В3!$H$44:$H$60,E$17) -> 0 | F22: =SUMIFS(Тек_карты_В3!$I$44:$I$60,Тек_карты_В3!$A$44:$A$60,$A22,Тек_карты_В3!$H$44:$H$60,F$17) -> 0 | G22: =SUMIFS(Тек_карты_В3!$I$44:$I$60,Тек_карты_В3!$A$44:$A$60,$A22,Тек_карты_В3!$H$44:$H$60,G$17) -> 0 | H22: =SUMIFS(Тек_карты_В3!$I$44:$I$60,Тек_карты_В3!$A$44:$A$60,$A22,Тек_карты_В3!$H$44:$H$60,H$17) -> 0
A23: Фарш домашний | B23: =SUMIFS(Тек_карты_В3!$I$44:$I$60,Тек_карты_В3!$A$44:$A$60,$A23,Тек_карты_В3!$H$44:$H$60,B$17) -> 0.05 | C23: =SUMIFS(Тек_карты_В3!$I$44:$I$60,Тек_карты_В3!$A$44:$A$60,$A23,Тек_карты_В3!$H$44:$H$60,C$17) -> 0.02 | D23: =SUMIFS(Тек_карты_В3!$I$44:$I$60,Тек_карты_В3!$A$44:$A$60,$A23,Тек_карты_В3!$H$44:$H$60,D$17) -> 0 | E23: =SUMIFS(Тек_карты_В3!$I$44:$I$60,Тек_карты_В3!$A$44:$A$60,$A23,Тек_карты_В3!$H$44:$H$60,E$17) -> 0 | F23: =SUMIFS(Тек_карты_В3!$I$44:$I$60,Тек_карты_В3!$A$44:$A$60,$A23,Тек_карты_В3!$H$44:$H$60,F$17) -> 0 | G23: =SUMIFS(Тек_карты_В3!$I$44:$I$60,Тек_карты_В3!$A$44:$A$60,$A23,Тек_карты_В3!$H$44:$H$60,G$17) -> 0 | H23: =SUMIFS(Тек_карты_В3!$I$44:$I$60,Тек_карты_В3!$A$44:$A$60,$A23,Тек_карты_В3!$H$44:$H$60,H$17) -> 0
A24: Фарш говяжий | B24: =SUMIFS(Тек_карты_В3!$I$44:$I$60,Тек_карты_В3!$A$44:$A$60,$A24,Тек_карты_В3!$H$44:$H$60,B$17) -> 0.05 | C24: =SUMIFS(Тек_карты_В3!$I$44:$I$60,Тек_карты_В3!$A$44:$A$60,$A24,Тек_карты_В3!$H$44:$H$60,C$17) -> 0.02 | D24: =SUMIFS(Тек_карты_В3!$I$44:$I$60,Тек_карты_В3!$A$44:$A$60,$A24,Тек_карты_В3!$H$44:$H$60,D$17) -> 0 | E24: =SUMIFS(Тек_карты_В3!$I$44:$I$60,Тек_карты_В3!$A$44:$A$60,$A24,Тек_карты_В3!$H$44:$H$60,E$17) -> 0 | F24: =SUMIFS(Тек_карты_В3!$I$44:$I$60,Тек_карты_В3!$A$44:$A$60,$A24,Тек_карты_В3!$H$44:$H$60,F$17) -> 0 | G24: =SUMIFS(Тек_карты_В3!$I$44:$I$60,Тек_карты_В3!$A$44:$A$60,$A24,Тек_карты_В3!$H$44:$H$60,G$17) -> 0 | H24: =SUMIFS(Тек_карты_В3!$I$44:$I$60,Тек_карты_В3!$A$44:$A$60,$A24,Тек_карты_В3!$H$44:$H$60,H$17) -> 0
A25: Тесто | B25: =SUMIFS(Тек_карты_В3!$I$44:$I$60,Тек_карты_В3!$A$44:$A$60,$A25,Тек_карты_В3!$H$44:$H$60,B$17) -> 0 | C25: =SUMIFS(Тек_карты_В3!$I$44:$I$60,Тек_карты_В3!$A$44:$A$60,$A25,Тек_карты_В3!$H$44:$H$60,C$17) -> 0 | D25: =SUMIFS(Тек_карты_В3!$I$44:$I$60,Тек_карты_В3!$A$44:$A$60,$A25,Тек_карты_В3!$H$44:$H$60,D$17) -> 0.2 | E25: =SUMIFS(Тек_карты_В3!$I$44:$I$60,Тек_карты_В3!$A$44:$A$60,$A25,Тек_карты_В3!$H$44:$H$60,E$17) -> 0 | F25: =SUMIFS(Тек_карты_В3!$I$44:$I$60,Тек_карты_В3!$A$44:$A$60,$A25,Тек_карты_В3!$H$44:$H$60,F$17) -> 0 | G25: =SUMIFS(Тек_карты_В3!$I$44:$I$60,Тек_карты_В3!$A$44:$A$60,$A25,Тек_карты_В3!$H$44:$H$60,G$17) -> 0 | H25: =SUMIFS(Тек_карты_В3!$I$44:$I$60,Тек_карты_В3!$A$44:$A$60,$A25,Тек_карты_В3!$H$44:$H$60,H$17) -> 0
A27: 3. Таблица. Станкоёмкость условного изделия по видам оборудования
A28: Вид оборудования | B28: Станкоёмкость изготовления условного изделия, нормо-ч/ед.
A29: Оборудование 1 | B29: =SUMPRODUCT(B$18:B$25,$C$6:$C$13) -> 0.02146345
A30: Оборудование 2 | B30: =SUMPRODUCT(C$18:C$25,$C$6:$C$13) -> 0.0081454286
A31: Оборудование 3 | B31: =SUMPRODUCT(D$18:D$25,$C$6:$C$13) -> 0.021643929
A32: Оборудование 4 | B32: =SUMPRODUCT(E$18:E$25,$C$6:$C$13) -> 0.024597929
A33: Оборудование 5 | B33: =SUMPRODUCT(F$18:F$25,$C$6:$C$13) -> 0.073793788
A34: Оборудование 6 | B34: =SUMPRODUCT(G$18:G$25,$C$6:$C$13) -> 0.0024879048
A35: Оборудование 7 | B35: =SUMPRODUCT(H$18:H$25,$C$6:$C$13) -> 0.041465081

Sheet Этап2_ФондВремени
A1: Этап 2. Фонд времени работы наличного оборудования — май 2018 г.
A2: Режим работы: 5-ти дневная неделя, 1 смена, 8 ч. Процесс прерывный ⇒ действительный (плановый) фонд Фд = Фр − (Рк + Рпп).
A4: 1. Исходные данные
A5: Плановый период | B5: май 2018 г.
A6: Календарные дни периода, Дк | B6: 31
A7: Выходные дни (суббота, воскресенье), Дв | B7: 8
A8: Праздничные дни, Дп (1 мая — Праздник Весны и Труда, 9 мая — День Победы) | B8: 2
A9: Рабочих дней в периоде = Дк − Дв − Дп | B9: =$B$6-$B$7-$B$8 -> 21
A10: Длительность смены, Дсм, ч | B10: 8
A11: Количество смен, Ксм | B11: 1
A12: Предпраздничные сокращённые дни, Дп.д | B12: 0
A13: Нерабочих часов в предпраздничные дни, tн | B13: 0
A14: Плановый ремонтный фонд, % (= Задание!B9) | B14: =Задание!$B$9 -> 0.3
A16: 2. Фонды времени единицы оборудования
A17: Календарный фонд, Фк = Дк × 24, ч | B17: =$B$6*24 -> 744
A18: Режимный (номинальный) фонд, Фр = (Дсм × (Дк − Дв − Дп) − tн × Дп.д) × Ксм, ч | B18: =($B$10*($B$6-$B$7-$B$8)-$B$13*$B$12)*$B$11 -> 168
A19: Ремонтный фонд от КАЛЕНДАРНОГО фонда (дословно по заданию), Рк + Рпп = % × Фк, ч | B19: =$B$14*$B$17 -> 223.2
A20: Ремонтный фонд от РЕЖИМНОГО фонда (уточнение для прерывного процесса), Рк + Рпп = % × Фр, ч | B20: =$B$14*$B$18 -> 50.4
A22: 3. Сценарный расчёт действительного фонда времени
A23: По заданию ремонтный фонд составляет 30 % от КАЛЕНДАРНОГО фонда, тогда как заданный режим работы (5 дней, 1 смена) даёт Фр = 168 ч, а 0,3 × Фк = 223,2 ч > Фр. Ремонт физически не может превышать режимный фонд, поэтому дословное прочтение задания рассмотрено как отдельный сценарий, а базовым принят сценарий А.
A24: Показатель | B24: Сценарий А (базовый): 30 % от Фр | C24: Сценарий Б (дословно): 30 % от Фк | D24: Сценарий В: 30 % от Фк, но ремонт ≤ Фр
A25: База расчёта ремонтного фонда, ч | B25: =$B$18 -> 168 | C25: =$B$17 -> 744 | D25: =$B$17 -> 744
A26: Ремонтный фонд, Рк + Рпп, ч | B26: =$B$14*B25 -> 50.4 | C26: =$B$14*C25 -> 223.2 | D26: =MIN($B$14*D25,$B$18) -> 168
A27: Действительный (плановый) фонд 1 ед. оборудования, Фд = Фр − (Рк+Рпп), ч | B27: =$B$18-B26 -> 117.6 | C27: =$B$18-C26 -> -55.2 | D27: =MAX(0,$B$18-D26) -> 0
A28: Допустимость сценария (Фд ≥ 0) | B28: =IF(B27>=0,"допустим","НЕДОПУСТИМ: Фд < 0") -> допустим | C28: =IF(C27>=0,"допустим","НЕДОПУСТИМ: Фд < 0") -> НЕДОПУСТИМ: Фд < 0 | D28: =IF(D27>=0,"допустим","НЕДОПУСТИМ: Фд < 0") -> допустим
A30: 4. Активный сценарий (выбирается в ячейке B31)
A31: Активный сценарий (1 = А, 2 = Б, 3 = В) | B31: 1
A32: Наименование активного сценария | B32: =CHOOSE(B31,"А: ремонт 30 % от режимного фонда","Б: ремонт 30 % от календарного фонда","В: ремонт 30 % от календарного фонда, но не более Фр") -> А: ремонт 30 % от режимного фонда
A33: Ремонтный фонд активного сценария, Рк + Рпп, ч | B33: =CHOOSE(B31,B26,C26,D26) -> 50.4
A34: Действительный фонд 1 единицы оборудования, Фд, ч | B34: =CHOOSE(B31,B27,C27,D27) -> 117.6
A36: 5. Таблица. Расчёт действительного фонда времени работы оборудования (по активному сценарию)
A37: Группа оборудования | B37: Количество единиц оборудования (k), шт. | C37: Действительный фонд времени единицы оборудования, ч | D37: Действительный фонд времени оборудования (группы), ч
A38: Оборудование 1 | B38: =Задание!$B$13 -> 2 | C38: =$B$34 -> 117.6 | D38: =B38*C38 -> 235.2
A39: Оборудование 2 | B39: =Задание!$B$14 -> 2 | C39: =$B$34 -> 117.6 | D39: =B39*C39 -> 235.2
A40: Оборудование 3 | B40: =Задание!$B$15 -> 1 | C40: =$B$34 -> 117.6 | D40: =B40*C40 -> 117.6
A41: Оборудование 4 | B41: =Задание!$B$16 -> 3 | C41: =$B$34 -> 117.6 | D41: =B41*C41 -> 352.8
A42: Оборудование 5 | B42: =Задание!$B$17 -> 4 | C42: =$B$34 -> 117.6 | D42: =B42*C42 -> 470.4
A43: Оборудование 6 | B43: =Задание!$B$18 -> 4 | C43: =$B$34 -> 117.6 | D43: =B43*C43 -> 470.4
A44: Оборудование 7 | B44: =Задание!$B$19 -> 1 | C44: =$B$34 -> 117.6 | D44: =B44*C44 -> 117.6
A45: ИТОГО | B45: =SUM(B38:B44) -> 17 | D45: =SUM(D38:D44) -> 1999.2
...

Sheet Этап3_Произв_мощность
A1: Этап 3. Расчёт производственной мощности на основе условного изделия (май 2018 г.)
A2: Пj = пропускная способность / норма времени на изготовление единицы условного изделия. Мощность цеха = min Пj в цехе; мощность предприятия = min Пj по цехам.
A3: Вид оборудования | B3: Действительный фонд работы 1 шт. оборудования, ч | C3: Количество единиц оборудования, шт. | D3: Пропускная способность, ч | E3: Норма времени на изготовление единицы условного изделия, нормо-ч/ед. | F3: Возможный выпуск — производственная мощность Пj, у.е. | G3: Потребность в условном изделии, у.е. | H3: Запас (+) / дефицит (−), у.е.
A4: Цех 1 (разделочный) — производство фарша
A5: Оборудование 1 | B5: =Этап2_ФондВремени!$C$38 -> 117.6 | C5: =Этап2_ФондВремени!$B$38 -> 2 | D5: =Этап2_ФондВремени!$D$38 -> 235.2 | E5: =Этап1_УсловнаяЕдиница!$B$29 -> 0.02146345 | F5: =D5/E5 -> 10958.164 | G5: =Расчет_МРП!$J$12+Расчет_МРП!$J$13+Расчет_МРП!$J$14 -> 736 | H5: =F5-G5 -> 10222.164
A6: Оборудование 2 | B6: =Этап2_ФондВремени!$C$39 -> 117.6 | C6: =Этап2_ФондВремени!$B$39 -> 2 | D6: =Этап2_ФондВремени!$D$39 -> 235.2 | E6: =Этап1_УсловнаяЕдиница!$B$30 -> 0.0081454286 | F6: =D6/E6 -> 28875.092 | G6: =Расчет_МРП!$J$12+Расчет_МРП!$J$13+Расчет_МРП!$J$14 -> 736 | H6: =F6-G6 -> 28139.092
A7: Цех 1 — производственная мощность цеха | B7: Х | C7: Х | D7: Х | E7: Х | F7: =MIN(F5,F6) -> 10958.164 | G7: =Расчет_МРП!$J$12+Расчет_МРП!$J$13+Расчет_МРП!$J$14 -> 736 | H7: =F7-G7 -> 10222.164
A8: Цех 2 (мучных заготовок) — производство теста и выпечка блинов
A9: Оборудование 3 | B9: =Этап2_ФондВремени!$C$40 -> 117.6 | C9: =Этап2_ФондВремени!$B$40 -> 1 | D9: =Этап2_ФондВремени!$D$40 -> 117.6 | E9: =Этап1_УсловнаяЕдиница!$B$31 -> 0.021643929 | F9: =D9/E9 -> 5433.3943 | G9: =Расчет_МРП!$J$15 -> 153.984 | H9: =F9-G9 -> 5279.4103
A10: Оборудование 6 | B10: =Этап2_ФондВремени!$C$43 -> 117.6 | C10: =Этап2_ФондВремени!$B$43 -> 4 | D10: =Этап2_ФондВремени!$D$43 -> 470.4 | E10: =Этап1_УсловнаяЕдиница!$B$34 -> 0.0024879048 | F10: =D10/E10 -> 189074.76 | G10: =Расчет_МРП!$J$11 -> 35.4 | H10: =F10-G10 -> 189039.36
A11: Цех 2 — производственная мощность цеха | B11: Х | C11: Х | D11: Х | E11: Х | F11: =MIN(F9,F10) -> 5433.3943 | G11: =Расчет_МРП!$J$15+Расчет_МРП!$J$11 -> 189.384 | H11: =F11-G11 -> 5244.0103
A12: Цех 3 (готовой продукции) — котлеты, пельмени, цыплёнок
A13: Оборудование 4 | B13: =Этап2_ФондВремени!$C$41 -> 117.6 | C13: =Этап2_ФондВремени!$B$41 -> 3 | D13: =Этап2_ФондВремени!$D$41 -> 352.8 | E13: =Этап1_УсловнаяЕдиница!$B$32 -> 0.024597929 | F13: =D13/E13 -> 14342.671 | G13: =Расчет_МРП!$J$6+Расчет_МРП!$J$8 -> 350 | H13: =F13-G13 -> 13992.671
A14: Оборудование 5 | B14: =Этап2_ФондВремени!$C$42 -> 117.6 | C14: =Этап2_ФондВремени!$B$42 -> 4 | D14: =Этап2_ФондВремени!$D$42 -> 470.4 | E14: =Этап1_УсловнаяЕдиница!$B$33 -> 0.073793788 | F14: =D14/E14 -> 6374.5203 | G14: =Расчет_МРП!$J$6+Расчет_МРП!$J$8 -> 350 | H14: =F14-G14 -> 6024.5203
A15: Оборудование 7 | B15: =Этап2_ФондВремени!$C$44 -> 117.6 | C15: =Этап2_ФондВремени!$B$44 -> 1 | D15: =Этап2_ФондВремени!$D$44 -> 117.6 | E15: =Этап1_УсловнаяЕдиница!$B$35 -> 0.041465081 | F15: =D15/E15 -> 2836.1213 | G15: =Расчет_МРП!$J$7 -> 147.5 | H15: =F15-G15 -> 2688.6213
A16: Цех 3 — производственная мощность цеха | B16: Х | C16: Х | D16: Х | E16: Х | F16: =MIN(F13,F14,F15) -> 2836.1213 | G16: =Расчет_МРП!$J$6+Расчет_МРП!$J$8+Расчет_МРП!$J$7 -> 497.5 | H16: =F16-G16 -> 2338.6213
A18: ПРЕДПРИЯТИЕ — производственная мощность (min Пj по цехам) | F18: =MIN(F7,F11,F16) -> 2836.1213
A19: ПРЕДПРИЯТИЕ — потребность в условном изделии (вся производственная программа), у.е. | G19: =Этап1_УсловнаяЕдиница!$B$14 -> 1422.884
A21: Запас (+) / дефицит (−) мощности предприятия, у.е. | F21: =F18-G19 -> 1413.2373
A22: Запас мощности, % к потребности | F22: =F18/G19-1 -> 0.99322034
A23: Уровень использования мощности (потребность / мощность), % | F23: =G19/F18 -> 0.50170068
A24: Коэффициент использования мощности (мощность / потребность) | F24: =F18/G19 -> 1.9932203
A25: Выполнение производственной программы | F25: =IF(F18>=G19,"программа обеспечивается (мощность достаточна)","МОЩНОСТИ НЕДОСТАТОЧНО — дефицит") -> программа обеспечивается (мощность достаточна)
A26: Ведущий (лимитирующий) цех | F26: =IF(F18=F7,"Цех 1 (разделочный)",IF(F18=F11,"Цех 2 (мучных заготовок)","Цех 3 (готовой продукции)")) -> Цех 3 (готовой продукции)
A27: Ведущее (лимитирующее) оборудование | F27: =IF(F18=F7,INDEX(A5:A6,MATCH(F7,F5:F6,0)),IF(F18=F11,INDEX(A9:A10,MATCH(F11,F9:F10,0)),INDEX(A13:A15,MATCH(F16,F13:F15,0)))) -> Оборудование 7
A28: Мощность ведущего оборудования, у.е. | F28: =F18 -> 2836.1213
A30: Примечание: «Потребность в условном изделии» по группам оборудования — объём производства изделий, изготавливаемых на этом оборудовании (по программе «Расчет_МРП»); по цехам — сумма изделий цеха. Сумма потребностей по трём цехам равна объёму всей программы.

Sheet Сравнение_Сценариев
A1: Сравнение сценариев расчёта ремонтного фонда (30 % от календарного / режимного фонда)
A3: Показатель | B3: Сценарий А (базовый) | C3: Сценарий Б (дословно) | D3: Сценарий В (ремонт ≤ Фр)
A4: База расчёта ремонтного фонда, ч | B4: =Этап2_ФондВремени!$B$25 -> 168 | C4: =Этап2_ФондВремени!$C$25 -> 744 | D4: =Этап2_ФондВремени!$D$25 -> 744
A5: Ремонтный фонд, Рк + Рпп, ч | B5: =Этап2_ФондВремени!$B$26 -> 50.4 | C5: =Этап2_ФондВремени!$C$26 -> 223.2 | D5: =Этап2_ФондВремени!$D$26 -> 168
A6: Действительный фонд 1 ед. оборудования, Фд, ч | B6: =Этап2_ФондВремени!$B$27 -> 117.6 | C6: =Этап2_ФондВремени!$C$27 -> -55.2 | D6: =Этап2_ФондВремени!$D$27 -> 0
A7: Допустимость | B7: =Этап2_ФондВремени!$B$28 -> допустим | C7: =Этап2_ФондВремени!$C$28 -> НЕДОПУСТИМ: Фд < 0 | D7: =Этап2_ФондВремени!$D$28 -> допустим
A9: Производственная мощность Пj по видам оборудования, у.е.
A10: Вид оборудования | B10: Станкоёмкость усл. изделия, нормо-ч/ед. | C10: Пj — сценарий А | D10: Пj — сценарий Б | E10: Пj — сценарий В
A11: Оборудование 1 | B11: =Этап1_УсловнаяЕдиница!$B$29 -> 0.02146345 | C11: =Задание!$B$13*Этап2_ФондВремени!$B$27/$B11 -> 10958.164 | D11: =Задание!$B$13*Этап2_ФондВремени!$C$27/$B11 -> -5143.6278 | E11: =Задание!$B$13*Этап2_ФондВремени!$D$27/$B11 -> 0
A12: Оборудование 2 | B12: =Этап1_УсловнаяЕдиница!$B$30 -> 0.0081454286 | C12: =Задание!$B$14*Этап2_ФондВремени!$B$27/$B12 -> 28875.092 | D12: =Задание!$B$14*Этап2_ФондВремени!$C$27/$B12 -> -13553.615 | E12: =Задание!$B$14*Этап2_ФондВремени!$D$27/$B12 -> 0
A13: Оборудование 3 | B13: =Этап1_УсловнаяЕдиница!$B$31 -> 0.021643929 | C13: =Задание!$B$15*Этап2_ФондВремени!$B$27/$B13 -> 5433.3943 | D13: =Задание!$B$15*Этап2_ФондВремени!$C$27/$B13 -> -2550.3688 | E13: =Задание!$B$15*Этап2_ФондВремени!$D$27/$B13 -> 0
A14: Оборудование 4 | B14: =Этап1_УсловнаяЕдиница!$B$32 -> 0.024597929 | C14: =Задание!$B$16*Этап2_ФондВремени!$B$27/$B14 -> 14342.671 | D14: =Задание!$B$16*Этап2_ФондВремени!$C$27/$B14 -> -6732.274 | E14: =Задание!$B$16*Этап2_ФондВремени!$D$27/$B14 -> 0
A15: Оборудование 5 | B15: =Этап1_УсловнаяЕдиница!$B$33 -> 0.073793788 | C15: =Задание!$B$17*Этап2_ФондВремени!$B$27/$B15 -> 6374.5203 | D15: =Задание!$B$17*Этап2_ФондВремени!$C$27/$B15 -> -2992.1218 | E15: =Задание!$B$17*Этап2_ФондВремени!$D$27/$B15 -> 0
A16: Оборудование 6 | B16: =Этап1_УсловнаяЕдиница!$B$34 -> 0.0024879048 | C16: =Задание!$B$18*Этап2_ФондВремени!$B$27/$B16 -> 189074.76 | D16: =Задание!$B$18*Этап2_ФондВремени!$C$27/$B16 -> -88749.375 | E16: =Задание!$B$18*Этап2_ФондВремени!$D$27/$B16 -> 0
A17: Оборудование 7 | B17: =Этап1_УсловнаяЕдиница!$B$35 -> 0.041465081 | C17: =Задание!$B$19*Этап2_ФондВремени!$B$27/$B17 -> 2836.1213 | D17: =Задание!$B$19*Этап2_ФондВремени!$C$27/$B17 -> -1331.2406 | E17: =Задание!$B$19*Этап2_ФондВремени!$D$27/$B17 -> 0
A19: Показатель | B19: Сценарий А | C19: Сценарий Б | D19: Сценарий В
A20: Цех 1 (ведущее оборудование цеха) | B20: =MIN(C11,C12) -> 10958.164 | C20: =MIN(D11,D12) -> -13553.615 | D20: =MIN(E11,E12) -> 0
A21: Цех 2 (ведущее оборудование цеха) | B21: =MIN(C13,C16) -> 5433.3943 | C21: =MIN(D13,D16) -> -88749.375 | D21: =MIN(E13,E16) -> 0
A22: Цех 3 (ведущее оборудование цеха) | B22: =MIN(C14,C15,C17) -> 2836.1213 | C22: =MIN(D14,D15,D17) -> -6732.274 | D22: =MIN(E14,E15,E17) -> 0
A23: ПРЕДПРИЯТИЕ (min по цехам) | B23: =MIN(B20:B22) -> 2836.1213 | C23: =MIN(C20:C22) -> -88749.375 | D23: =MIN(D20:D22) -> 0
A24: Потребность в условном изделии (программа), у.е. | B24: =Этап1_УсловнаяЕдиница!$B$14 -> 1422.884 | C24: =Этап1_УсловнаяЕдиница!$B$14 -> 1422.884 | D24: =Этап1_УсловнаяЕдиница!$B$14 -> 1422.884
A25: Запас (+) / дефицит (−), у.е. | B25: =B23-B24 -> 1413.2373 | C25: =C23-C24 -> -90172.259 | D25: =D23-D24 -> -1422.884
A26: Запас мощности, % к потребности | B26: =IFERROR(B23/B24,"н/д") -> 1.9932203 | C26: =IFERROR(C23/C24,"н/д") -> -62.372881 | D26: =IFERROR(D23/D24,"н/д") -> 0
A27: Уровень использования мощности, % | B27: =IFERROR(B24/B23,"н/д") -> 0.50170068 | C27: =IFERROR(C24/C23,"н/д") -> -0.016032609 | D27: =IFERROR(D24/D23,"н/д") -> н/д
A28: Выполнение программы | B28: =IF(B23>=B24,"мощность достаточна","ДЕФИЦИТ мощности") -> мощность достаточна | C28: =IF(C23>=C24,"мощность достаточна","ДЕФИЦИТ мощности") -> ДЕФИЦИТ мощности | D28: =IF(D23>=D24,"мощность достаточна","ДЕФИЦИТ мощности") -> ДЕФИЦИТ мощности
A30: Вывод: сценарий А (ремонт 30 % от режимного фонда) — единственный физически реализуемый вариант с положительным действительным фондом ⇒ принят базовым (в книге активен по умолчанию).
A31: Сценарий Б (дословно 30 % от календарного фонда) даёт отрицательный действительный фонд: ремонт (223,2 ч) больше режимного фонда (168 ч) — недопустим.
A32: Сценарий В (предельный) даёт Фд = 0: ремонт полностью поглощает режимный фонд, рабочего времени нет, программа невыполнима.

Sheet Выводы
A1: Выводы по лабораторной работе №6 (вариант 3, май 2018 г.)
A3: 1. Производственная программа (проект ППМ, уровни 0-1) рассчитана методом MRP — лист «Расчет_МРП».
A4: 2. Нормы станкоёмкости условного изделия по 7 видам оборудования — лист «Этап1_УсловнаяЕдиница», п. 3.
A5: 3. Фонды времени работы наличного оборудования — лист «Этап2_ФондВремени».
A6: 4. Производственная мощность по цехам и предприятию — лист «Этап3_Произв_мощность».
A7: 5. Сценарный анализ базы ремонтного фонда — лист «Сравнение_Сценариев».
A9: Ключевые результаты (подставляются формулами):
A10: Общий объём производственной программы (уровни 0-1), кг | B10: =Расчет_МРП!$J$16 -> 1422.884
A11: Станкоёмкость условного изделия по оборудованию 1…7, нормо-ч/ед. | B11: =TEXT(Этап1_УсловнаяЕдиница!$B$29,"0.000000")&" / "&TEXT(Этап1_УсловнаяЕдиница!$B$30,"0.000000")&" / "&TEXT(Этап1_УсловнаяЕдиница!$B$31,"0.000000")&" / "&TEXT(Этап1_УсловнаяЕдиница!$B$32,"0.000000")&" / "&TEXT(Этап1_УсловнаяЕдиница!$B$33,"0.000000")&" / "&TEXT(Этап1_УсловнаяЕдиница!$B$34,"0.000000")&" / "&TEXT(Этап1_УсловнаяЕдиница!$B$35,"0.000000") -> 0.021463 / 0.008145 / 0.021644 / 0.024598 / 0.073794 / 0.002488 / 0.041465
A12: Календарный фонд единицы оборудования Фк, ч | B12: =Этап2_ФондВремени!$B$17 -> 744
A13: Режимный фонд единицы оборудования Фр, ч | B13: =Этап2_ФондВремени!$B$18 -> 168
A14: Активный сценарий расчёта ремонтного фонда | B14: =Этап2_ФондВремени!$B$32 -> А: ремонт 30 % от режимного фонда
A15: Действительный фонд 1 единицы оборудования Фд, ч | B15: =Этап2_ФондВремени!$B$34 -> 117.6
A16: Мощность цеха 1 (разделочный), у.е. | B16: =Этап3_Произв_мощность!$F$7 -> 10958.164
A17: Мощность цеха 2 (мучных заготовок), у.е. | B17: =Этап3_Произв_мощность!$F$11 -> 5433.3943
A18: Мощность цеха 3 (готовой продукции), у.е. | B18: =Этап3_Произв_мощность!$F$16 -> 2836.1213
A19: НАЛИЧНАЯ ПРОИЗВОДСТВЕННАЯ МОЩНОСТЬ ПРЕДПРИЯТИЯ, у.е. | B19: =Этап3_Произв_мощность!$F$18 -> 2836.1213
A20: Потребность в условном изделии (программа), у.е. | B20: =Этап3_Произв_мощность!$G$19 -> 1422.884
A21: Запас (+) / дефицит (−) мощности, у.е. | B21: =Этап3_Произв_мощность!$F$21 -> 1413.2373
A22: Запас мощности, % к потребности | B22: =Этап3_Произв_мощность!$F$22 -> 0.99322034
A23: Коэффициент использования мощности (во сколько раз мощность больше потребности) | B23: =Этап3_Произв_мощность!$F$24 -> 1.9932203
A24: Ведущий (лимитирующий) цех | B24: =Этап3_Произв_мощность!$F$26 -> Цех 3 (готовой продукции)
A25: Ведущее (лимитирующее) оборудование | B25: =Этап3_Произв_мощность!$F$27 -> Оборудование 7
A26: Выполнение производственной программы | B26: =Этап3_Произв_мощность!$F$25 -> программа обеспечивается (мощность достаточна)
A28: Пояснения и принятые допущения — в отчёте «ЛР6 Производственная мощность В3 (решение).md».

Sheet Sheet1
