Workbook

Sheet Задание
B2: Предприятие выпускает и реализует котлеты киевские, цыплята фаршированные, пельмени.
B6: Производство организовано в цехах:
B7: №1. В разделочном цехе выполняют операции по производству фарша
B8: №2. В цехе мучных заготовок выполняют операции по производству теста и выпечки блинов
B9: №3. В цехе готовой продукции выполняют операции по производству готовой продукции
B12: Определить потребность в материалах на период с учетом данных, представленных на листах "Основные данные", "Остатки материалов", "Заказы клиентов"

Sheet ОсновныеДанные
A2: 1. | B2: Спецификация "Фарш говяжий" | C2: 1 кг | F2: Технологическая карта "Фарш говяжий" | H2: 100 кг
B3: Материал | C3: норма | D3: ед.изм. | F3: операция | G3: цех | H3: трудоем., чел-час | I3: станкоемк., маш-ч | J3: оборудование | K3: материалы
B4: говядина | C4: 0.8 | D4: кг | F4: разрезка мяса на куски | G4: №1 | H4: 5 | I4: 5 | J4: оборудование 1 | K4: по спецификации
B5: яйцо | C5: 2 | D5: шт. | F5: приготовление фарша | G5: №1 | H5: 2 | I5: 2 | J5: оборудование 2
B6: лук репчатый | C6: 0.02 | D6: кг
B7: перец | C7: 0.001 | D7: кг
B8: соль | C8: 0.001 | D8: кг
A11: 2. | B11: Спецификация "Фарш домашний" | C11: 1 кг | F11: Технологическая карта "Фарш домашний" | H11: 100 кг
B12: Материал | C12: норма | D12: ед.изм. | F12: операция | G12: цех | H12: трудоем., чел-час | I12: станкоемк., маш-ч | J12: оборудование | K12: материалы
B13: говядина | C13: 0.6 | D13: кг | F13: разрезка мяса на куски | G13: №1 | H13: 5 | I13: 5 | J13: оборудование 1 | K13: по спецификации
B14: Свинина | C14: 0.2 | D14: кг | F14: приготовление фарша | G14: №1 | H14: 2 | I14: 2 | J14: оборудование 2
B15: яйцо | C15: 2 | D15: шт.
B16: лук репчатый | C16: 0.02 | D16: кг
B17: перец | C17: 0.001 | D17: кг
B18: соль | C18: 0.001 | D18: кг
A20: 3. | B20: Спецификация "Фарш куриный" | C20: 1 кг | F20: Технологическая карта "Фарш куриный" | H20: 100 кг
B21: Материал | C21: норма | D21: ед.изм. | F21: операция | G21: цех | H21: трудоем., чел-час | I21: станкоемк., маш-ч | J21: оборудование | K21: материалы
B22: тушка цыпленка | C22: 0.6 | D22: кг | F22: разрезка мяса на куски | G22: №1 | H22: 4 | I22: 4 | J22: оборудование 1 | K22: по спецификации
B23: яйцо | C23: 2 | D23: шт. | F23: приготовление фарша | G23: №1 | H23: 1.5 | I23: 1.5 | J23: оборудование 2
B24: лук репчатый | C24: 0.02 | D24: кг
B25: перец | C25: 0.001 | D25: кг
B26: соль | C26: 0.001 | D26: кг
A28: 4. | B28: Спецификация "Тесто" | C28: 1 кг | F28: Технологическая карта "Тесто" | H28: 10 кг
B29: Материал | C29: норма | D29: ед.изм. | F29: операция | G29: цех | H29: трудоем., чел-час | I29: станкоемк., маш-ч | J29: оборудование | K29: материалы
B30: мука | C30: 0.9 | D30: кг | F30: приготовление теста | G30: №2 | H30: 2 | I30: 2 | J30: оборудование 3 | K30: по спецификации
B31: яйцо | C31: 1 | D31: шт.
B32: сахар | C32: 0.02 | D32: кг
B33: соль | C33: 0.002 | D33: кг
B34: разрыхлитель для теста | C34: 0.003 | D34: кг
A35: 5. | B35: Спецификация "Пельмени из говядины" | C35: 1 кг | F35: Технологическая карта "Пельмени из говядины" | H35: 10кг
B36: Материал | C36: норма | D36: ед.изм. | F36: операция | G36: цех | H36: трудоем., чел-час | I36: станкоемк., маш-ч | J36: оборудование | K36: материалы
B37: Фарш говяжий | C37: 0.7 | D37: кг | F37: Лепка пельменей | G37: №3 | H37: 0.5 | I37: 0.5 | J37: оборудование 4 | K37: Фарш говяжий, тесто
B38: Тесто | C38: 0.3 | D38: кг. | F38: Заморозка пельменей | G38: №3 | I38: 3 | J38: оборудование 5
A40: 6. | B40: Спецификация "Пельмени домашние" | C40: 1 кг | F40: Технологическая карта "Пельмени домашние" | H40: 10кг
B41: Материал | C41: норма | D41: ед.изм. | F41: операция | G41: цех | H41: трудоем., чел-час | I41: станкоемк., маш-ч | J41: оборудование | K41: материалы
B42: Фарш домашний | C42: 0.7 | D42: кг | F42: Лепка пельменей | G42: №3 | H42: 0.5 | I42: 0.5 | J42: оборудование 4 | K42: Фарш домашний, тесто
B43: Тесто | C43: 0.3 | D43: кг. | F43: Заморозка пельменей | G43: №3 | I43: 3 | J43: оборудование 5
A45: 7. | B45: Спецификация "Котлета по киевски" | C45: 1 кг | F45: Технологическая карта "Котлета по киевски" | H45: 10кг
B46: Материал | C46: норма | D46: ед.изм. | F46: операция | G46: цех | H46: трудоем., чел-час | I46: станкоемк., маш-ч | J46: оборудование | K46: материалы
B47: Фарш куриный | C47: 0.8 | D47: кг | F47: Лепка котлеты | G47: №3 | H47: 1 | I47: 1 | J47: оборудование 4 | K47: Фарш куриный, масло сливочное, петрушка
...

Sheet СкладОстатки
A2: 1. | B2: Остатки на начало периода готовой продукции | C2: Кол-во | D2: ед.изм.
B3: Котлеты киевские | C3: 25 | D3: кг
B4: Цыплята фаршированные | C4: 40 | D4: кг
B5: пельмени домашние | C5: 10 | D5: кг
A7: 2. | B7: Политика запасов готовой продукции
B8: На конец периода запас должен составлять % от потребности текущего периода | C8: 25
A10: 3. | B10: Остатки на начало периода полуфабрикатов
B11: фарш говяжий | C11: 45 | D11: кг
B12: фарш куриный | C12: 10 | D12: кг
B13: фарш говяжий | C13: 70 | D13: кг
A15: 4. | B15: Политика запасов полуфабрикатов
B16: На конец периода запас должен составлять % от потребности текущего периода | C16: 20
A18: 5. | B18: Остатки на начало периода материалов
B19: говядина | C19: 50 | D19: кг
B20: свинина | C20: 2 | D20: кг
B21: цыплята | C21: 70 | D21: кг
B22: яйцо | C22: 80 | D22: шт
B23: лук репчатый | C23: 9 | D23: кг
B24: перец черный | C24: 2 | D24: кг
B25: мука | C25: 50 | D25: кг
B26: соль | C26: 10 | D26: кг
B27: разрыхлитель для теста | C27: 100 | D27: гр
B28: лук зеленый | C28: 15 | D28: кг
B29: петрушка свежая | C29: 5 | D29: кг
A31: 6. | B31: Политика запасов материалов
B32: На конец периода запас должен составлять % от потребности текущего периода | C32: 15

Sheet ЗаказыКлиентов
B3: Заказы клиентов
B4: Котлеты по киевски | C4: 300 | D4: кг.
B5: Тесто | C5: 100 | D5: кг.
B6: Фарш куриный | C6: 250 | D6: кг.
B7: Фарш домашний | C7: 150 | D7: кг.
B8: Цыпленок фаршированный | C8: 150 | D8: кг.

Sheet Расчет_ППМ
A1: Таблица. Потребность в материалах на период
A3: Уровень | B3: Материал | C3: Ед. изм. | D3: Остаток на начало | E3: Заказы клиентов | F3: Зависимая потребность | G3: Общая потребность | H3: % запаса | I3: Остаток на конец (норматив) | J3: Объем производства | K3: Объем закупки | L3: Остаток на конец
A4: Уровень 0. Готовая продукция (норматив запаса — «СкладОстатки»!C8 = 25%)
A5: 0 | B5: Котлета по-киевски | C5: кг | D5: =СкладОстатки!C3 -> 25 | E5: =ЗаказыКлиентов!C4 -> 300 | F5: 0 | G5: =E5+F5 -> 300 | H5: =СкладОстатки!$C$8/100 -> 0.25 | I5: =H5*G5 -> 75 | J5: =MAX(0,G5+I5-D5) -> 350 | K5: 0 | L5: =D5+J5+K5-G5 -> 75
A6: 0 | B6: Цыпленок фаршированный | C6: кг | D6: =СкладОстатки!C4 -> 40 | E6: =ЗаказыКлиентов!C8 -> 150 | F6: 0 | G6: =E6+F6 -> 150 | H6: =СкладОстатки!$C$8/100 -> 0.25 | I6: =H6*G6 -> 37.5 | J6: =MAX(0,G6+I6-D6) -> 147.5 | K6: 0 | L6: =D6+J6+K6-G6 -> 37.5
A7: 0 | B7: Пельмени домашние | C7: кг | D7: =СкладОстатки!C5 -> 10 | E7: 0 | F7: 0 | G7: =E7+F7 -> 0 | H7: =СкладОстатки!$C$8/100 -> 0.25 | I7: =H7*G7 -> 0 | J7: =MAX(0,G7+I7-D7) -> 0 | K7: 0 | L7: =D7+J7+K7-G7 -> 10
A9: Уровень 1. Полуфабрикаты (норматив запаса — «СкладОстатки»!C16 = 20%)
A10: 1 | B10: Блины | C10: кг | D10: 0 | E10: 0 | F10: =J6*ОсновныеДанные!C60 -> 29.5 | G10: =E10+F10 -> 29.5 | H10: =СкладОстатки!$C$16/100 -> 0.2 | I10: =H10*G10 -> 5.9 | J10: =MAX(0,G10+I10-D10) -> 35.4 | K10: 0 | L10: =D10+J10+K10-G10 -> 5.9
A11: 1 | B11: Фарш куриный | C11: кг | D11: =СкладОстатки!C12 -> 10 | E11: =ЗаказыКлиентов!C6 -> 250 | F11: =J5*ОсновныеДанные!C47 -> 280 | G11: =E11+F11 -> 530 | H11: =СкладОстатки!$C$16/100 -> 0.2 | I11: =H11*G11 -> 106 | J11: =MAX(0,G11+I11-D11) -> 626 | K11: 0 | L11: =D11+J11+K11-G11 -> 106
A12: 1 | B12: Фарш домашний | C12: кг | D12: =СкладОстатки!C13 -> 70 | E12: =ЗаказыКлиентов!C7 -> 150 | F12: =J7*ОсновныеДанные!C42 -> 0 | G12: =E12+F12 -> 150 | H12: =СкладОстатки!$C$16/100 -> 0.2 | I12: =H12*G12 -> 30 | J12: =MAX(0,G12+I12-D12) -> 110 | K12: 0 | L12: =D12+J12+K12-G12 -> 30
A13: 1 | B13: Фарш говяжий | C13: кг | D13: =СкладОстатки!C11 -> 45 | E13: 0 | F13: 0 | G13: =E13+F13 -> 0 | H13: =СкладОстатки!$C$16/100 -> 0.2 | I13: =H13*G13 -> 0 | J13: =MAX(0,G13+I13-D13) -> 0 | K13: 0 | L13: =D13+J13+K13-G13 -> 45
A14: 1 | B14: Тесто | C14: кг | D14: 0 | E14: =ЗаказыКлиентов!C5 -> 100 | F14: =J10*ОсновныеДанные!C54+J7*ОсновныеДанные!C43 -> 28.32 | G14: =E14+F14 -> 128.32 | H14: =СкладОстатки!$C$16/100 -> 0.2 | I14: =H14*G14 -> 25.664 | J14: =MAX(0,G14+I14-D14) -> 153.984 | K14: 0 | L14: =D14+J14+K14-G14 -> 25.664
A16: Уровень 2. Закупаемые материалы (норматив запаса — «СкладОстатки»!C32 = 15%)
A17: 2 | B17: Говядина | C17: кг | D17: =СкладОстатки!C19 -> 50 | E17: 0 | F17: =J13*ОсновныеДанные!C4+J12*ОсновныеДанные!C13 -> 66 | G17: =E17+F17 -> 66 | H17: =СкладОстатки!$C$32/100 -> 0.15 | I17: =H17*G17 -> 9.9 | J17: 0 | K17: =MAX(0,G17+I17-D17) -> 25.9 | L17: =D17+J17+K17-G17 -> 9.9
A18: 2 | B18: Свинина | C18: кг | D18: =СкладОстатки!C20 -> 2 | E18: 0 | F18: =J12*ОсновныеДанные!C14 -> 22 | G18: =E18+F18 -> 22 | H18: =СкладОстатки!$C$32/100 -> 0.15 | I18: =H18*G18 -> 3.3 | J18: 0 | K18: =MAX(0,G18+I18-D18) -> 23.3 | L18: =D18+J18+K18-G18 -> 3.3
A19: 2 | B19: Тушка цыпленка | C19: кг | D19: =СкладОстатки!C21 -> 70 | E19: 0 | F19: =J11*ОсновныеДанные!C22+J6*ОсновныеДанные!C59 -> 493.6 | G19: =E19+F19 -> 493.6 | H19: =СкладОстатки!$C$32/100 -> 0.15 | I19: =H19*G19 -> 74.04 | J19: 0 | K19: =MAX(0,G19+I19-D19) -> 497.64 | L19: =D19+J19+K19-G19 -> 74.04
A20: 2 | B20: Яйцо | C20: шт. | D20: =СкладОстатки!C22 -> 80 | E20: 0 | F20: =J13*ОсновныеДанные!C5+J12*ОсновныеДанные!C15+J11*ОсновныеДанные!C23+J14*ОсновныеДанные!C31 -> 1625.984 | G20: =E20+F20 -> 1625.984 | H20: =СкладОстатки!$C$32/100 -> 0.15 | I20: =H20*G20 -> 243.8976 | J20: 0 | K20: =MAX(0,G20+I20-D20) -> 1789.8816 | L20: =D20+J20+K20-G20 -> 243.8976
A21: 2 | B21: Лук репчатый | C21: кг | D21: =СкладОстатки!C23 -> 9 | E21: 0 | F21: =J13*ОсновныеДанные!C6+J12*ОсновныеДанные!C16+J11*ОсновныеДанные!C24 -> 14.72 | G21: =E21+F21 -> 14.72 | H21: =СкладОстатки!$C$32/100 -> 0.15 | I21: =H21*G21 -> 2.208 | J21: 0 | K21: =MAX(0,G21+I21-D21) -> 7.928 | L21: =D21+J21+K21-G21 -> 2.208
A22: 2 | B22: Перец черный | C22: кг | D22: =СкладОстатки!C24 -> 2 | E22: 0 | F22: =J13*ОсновныеДанные!C7+J12*ОсновныеДанные!C17+J11*ОсновныеДанные!C25 -> 0.736 | G22: =E22+F22 -> 0.736 | H22: =СкладОстатки!$C$32/100 -> 0.15 | I22: =H22*G22 -> 0.1104 | J22: 0 | K22: =MAX(0,G22+I22-D22) -> 0 | L22: =D22+J22+K22-G22 -> 1.264
A23: 2 | B23: Соль | C23: кг | D23: =СкладОстатки!C26 -> 10 | E23: 0 | F23: =J13*ОсновныеДанные!C8+J12*ОсновныеДанные!C18+J11*ОсновныеДанные!C26+J14*ОсновныеДанные!C33 -> 1.043968 | G23: =E23+F23 -> 1.043968 | H23: =СкладОстатки!$C$32/100 -> 0.15 | I23: =H23*G23 -> 0.1565952 | J23: 0 | K23: =MAX(0,G23+I23-D23) -> 0 | L23: =D23+J23+K23-G23 -> 8.956032
A24: 2 | B24: Мука | C24: кг | D24: =СкладОстатки!C25 -> 50 | E24: 0 | F24: =J14*ОсновныеДанные!C30 -> 138.5856 | G24: =E24+F24 -> 138.5856 | H24: =СкладОстатки!$C$32/100 -> 0.15 | I24: =H24*G24 -> 20.78784 | J24: 0 | K24: =MAX(0,G24+I24-D24) -> 109.37344 | L24: =D24+J24+K24-G24 -> 20.78784
A25: 2 | B25: Сахар | C25: кг | D25: 0 | E25: 0 | F25: =J14*ОсновныеДанные!C32 -> 3.07968 | G25: =E25+F25 -> 3.07968 | H25: =СкладОстатки!$C$32/100 -> 0.15 | I25: =H25*G25 -> 0.461952 | J25: 0 | K25: =MAX(0,G25+I25-D25) -> 3.541632 | L25: =D25+J25+K25-G25 -> 0.461952
A26: 2 | B26: Разрыхлитель для теста | C26: кг | D26: =СкладОстатки!C27/1000 -> 0.1 | E26: 0 | F26: =J14*ОсновныеДанные!C34 -> 0.461952 | G26: =E26+F26 -> 0.461952 | H26: =СкладОстатки!$C$32/100 -> 0.15 | I26: =H26*G26 -> 0.0692928 | J26: 0 | K26: =MAX(0,G26+I26-D26) -> 0.4312448 | L26: =D26+J26+K26-G26 -> 0.0692928
A27: 2 | B27: Масло сливочное | C27: кг | D27: 0 | E27: 0 | F27: =J5*ОсновныеДанные!C48+J10*ОсновныеДанные!C55 -> 77.08 | G27: =E27+F27 -> 77.08 | H27: =СкладОстатки!$C$32/100 -> 0.15 | I27: =H27*G27 -> 11.562 | J27: 0 | K27: =MAX(0,G27+I27-D27) -> 88.642 | L27: =D27+J27+K27-G27 -> 11.562
A28: 2 | B28: Сухари панировочные | C28: кг | D28: 0 | E28: 0 | F28: =J5*ОсновныеДанные!C49 -> 70 | G28: =E28+F28 -> 70 | H28: =СкладОстатки!$C$32/100 -> 0.15 | I28: =H28*G28 -> 10.5 | J28: 0 | K28: =MAX(0,G28+I28-D28) -> 80.5 | L28: =D28+J28+K28-G28 -> 10.5
A29: 2 | B29: Петрушка | C29: кг | D29: =СкладОстатки!C29 -> 5 | E29: 0 | F29: =J5*ОсновныеДанные!C50+J6*ОсновныеДанные!C62 -> 24.875 | G29: =E29+F29 -> 24.875 | H29: =СкладОстатки!$C$32/100 -> 0.15 | I29: =H29*G29 -> 3.73125 | J29: 0 | K29: =MAX(0,G29+I29-D29) -> 23.60625 | L29: =D29+J29+K29-G29 -> 3.73125
A30: 2 | B30: Лук зеленый | C30: кг | D30: =СкладОстатки!C28 -> 15 | E30: 0 | F30: =J6*ОсновныеДанные!C61 -> 29.5 | G30: =E30+F30 -> 29.5 | H30: =СкладОстатки!$C$32/100 -> 0.15 | I30: =H30*G30 -> 4.425 | J30: 0 | K30: =MAX(0,G30+I30-D30) -> 18.925 | L30: =D30+J30+K30-G30 -> 4.425
A31: 2 | B31: Пленка пищевая | C31: м.кв | D31: 0 | E31: 0 | F31: =J6*ОсновныеДанные!C63 -> 29.5 | G31: =E31+F31 -> 29.5 | H31: =СкладОстатки!$C$32/100 -> 0.15 | I31: =H31*G31 -> 4.425 | J31: 0 | K31: =MAX(0,G31+I31-D31) -> 33.925 | L31: =D31+J31+K31-G31 -> 4.425
A33: Примечания: 1) Расчёт выполнен методом планирования потребности в материалах (MRP) в обратном ходе технологического процесса: уровень 0 → 1 → 2. 2) Независимый спрос (графа «Заказы клиентов») берётся с листа «ЗаказыКлиентов». Зависимый спрос (графа «Зависимая потребность») рассчитывается как сумма произведений объёма производства позиции верхнего уровня на норму расхода из «ОсновныеДанные». 3) Общая потребность = Заказы клиентов + Зависимая потребность. 4) Остаток на конец (норматив) = % запаса × Общая потребность. Нормативы: готовая продукция 25% («СкладОстатки»!C8), полуфабрикаты 20% («СкладОстатки»!C16), материалы 15% («СкладОстатки»!C32). 5) Объём производства (уровни 0–1) / Объём закупки (уровень 2) = MAX(0; Общая потребность + Остаток на конец (норматив) − Остаток на начало). 6) Остаток на конец (факт.) = Остаток на начало + Объём производства + Объём закупки − Общая потребность. 7) Нормы и исходные данные не изменялись, расчёт выполнен только формулами и ссылками. 8) Спецификация «Пельмени из говядины» в расчёт не включена: заказов клиентов на неё нет и она не является компонентом другой продукции. Поэтому «Фарш говяжий» имеет нулевую потребность и не производится. 9) По «Пельмени домашние» и «Блины» заказов клиентов в варианте 3 нет — весь объём выпуска обусловлен зависимой потребностью. 10) В листе «СкладОстатки» позиция B13 «фарш говяжий» (70 кг) продублирована по названию с позицией B11; по смыслу (поз. B13) это остаток «Фарша домашнего», он и использован в строке 12. 11) Разрыхлитель для теста: остаток (100 гр) пересчитан в кг делением на 1000.
